Workbook
Name Display: [1]!テーブル3[Display]
Name Elec: [1]!テーブル7[Elec]
Name Material: [1]!テーブル5[Material]
Name Mecha: [1]!テーブル6[Mecha]
Name Package: [1]!テーブル2[Package]
Name Product: [1]!テーブル4[Product]
Name SQLリスト: SQL[SQL Type]
Name 分類1: [1]!テーブル1[分類１]

Sheet <SQL> 
B3: =COLUMNS($B$2:B$2) -> 1 | C3: =COLUMNS($B$2:C$2) -> 2 | D3: =COLUMNS($B$2:D$2) -> 3 | E3: =COLUMNS($B$2:E$2) -> 4 | F3: =COLUMNS($B$2:F$2) -> 5 | G3: =COLUMNS($B$2:G$2) -> 6
B5: SQL Type | C5: offset | D5: 列12 | E5: テーブル | F5: 列14
B6: SQLite | C6: 0 | E6: =COLUMNS($B$2:E$2) -> 4 | G6: 6
B7: SQL Server | C7: 1 | E7: =COLUMNS($B$2:F$2) -> 5
B8: MongoDB | C8: 2 | E8: =COLUMNS($B$2:G$2) -> 6
B11: Type | C11: Desc | D11: Note | E11: SQLite | F11: SQL Server | G11: MongoDB
B12: INT | C12: 整数型 | D12: 一般的な整数型。範囲は -2,147,483,648 から 2,147,483,647。 | E12: INTEGER
B13: SMALLINT | C13: 整数型 | D13: 小さめの整数型。範囲は -32,768 から 32,767。 | E13: INTEGER
B14: TINYINT | C14: 整数型 | D14: 非常に小さい整数型。範囲は 0 から 255（符号なし）または -128 から 127（符号あり）。 | E14: INTEGER
B15: BIGINT | C15: 整数型 | D15: 大きな整数型。範囲は -9,223,372,036,854,775,808 から 9,223,372,036,854,775,807。 | E15: INTEGER
B16: FLOAT | C16: 浮動小数点型 | D16: 単精度の浮動小数点型。精度と範囲は実装に依存。 | E16: REAL
B17: REAL | C17: 浮動小数点型 | D17: 浮動小数点型。通常、FLOATと同義で使用されるが、精度は実装に依存。 | E17: REAL
B18: DECIMAL | C18: 固定小数点型 | D18: 精度を指定できる固定小数点型。主に金額などの精度が重要なデータに使用。 | E18: REAL
B19: NUMERIC | C19: 固定小数点型 | D19: DECIMALと同義。精度を指定できる固定小数点型 | E19: REAL
B20: CHAR | C20: 固定長文字列型 | D20: 固定長の文字列を格納するためのデータ型です。データの長さが指定された文字数に満たない場合、残りのスペースは空白文字で埋められます。 | E20: TEXT
B21: VARCHAR | C21: 可変長文字列型 | D21: 可変長の文字列を格納するためのデータ型です。格納するデータの長さに応じて、必要な分だけのストレージが使用されます。指定された長さの上限を超えるデータは格納できません。 | E21: TEXT
B22: TEXT | C22: 大文字列型 | D22: 非常に長い可変長の文字列を格納するためのデータ型です。通常、VARCHAR よりも大きなサイズの文字列を格納するために使用されます。データベースごとに制限が異なりますが、かなりの大容量を扱うことが可能です。 | E22: TEXT
B23: CLOB | C23: 大文字列型 | D23: 大規模な文字データを格納するためのデータ型です。TEXT と同様に非常に長い文字列を扱うことができますが、データベースシステムによっては異なる内部処理や制限がある場合があります。 | E23: TEXT
... B34: BLOB | C34: 大バイナリ型 | D34: 大きなバイナリデータ（Binary Large Object）を格納する | E34: BLOB
B35: NULL | E35: NULL
B38: NOT NULL | C38: Desc | D38: Note | E38: SQLite | F38: SQL Server | G38: MongoDB
B39: Y | C39: 対応 | E39: NOT NULL
B40: N | C40: 非対応
C41: 非対応
B44: PK | C44: Desc | D44: Note | E44: SQLite | F44: SQL Server | G44: MongoDB
B45: Y | C45: 対応 | E45: PRIMARY KEY
B46: N | C46: 非対応
C47: 非対応
B50: FK | C50: Desc | D50: Note | E50: SQLite | F50: SQL Server | G50: MongoDB
B51: Y | C51: 対応
B52: N | C52: 非対応
C53: 非対応

Sheet Table>
A2: https://www.blog.furusuzu0530.com/development-2/
O3: KEY_KEY_CAT_TYPE : Final[str] = "KEY_CAT_TYPE"# キー大分類キー
B5: 論理名 | C5: SQLite | O5: 100
O6: 44
N7: CSV | O7: PYTHON
A8: 基準種類DB
B9: テーブル名 | C9: 物理名 | D9: tbl_cat_type | N9: =UPPER( D9 ) & "," &D9 & ",," -> TBL_CAT_TYPE,tbl_cat_type,, | O9: =LEFT( LEFT("KEY_"&UPPER(D9)&REPT(" ",$O$6),$O$6) & ": Final[str] = """&UPPER(D9)&"""" & REPT(" ",$O$5),$O$5 ) & "# " &D10 -> KEY_TBL_CAT_TYPE : Final[str] = "TBL_CAT_TYPE" # 基準類テーブル
C10: 論理名 | D10: 基準類テーブル
B11: カラム名 | E11: データ型 | J11: 制約 | N11: CREATE
B12: 物理名 | C12: 論理名 | D12: 概要 | E12: Type | F12: Byte | G12: SQLite | H12: SQL Server | I12: MongoDB | J12: NOT_NULL | K12: PK | L12: FK | N12: CSV | P12: SQLite | Q12: SQL Server | R12: MongoDB
B13: =OFFSET( tbl_cat_type[[#Headers],[key_cat_type]], 0, ROWS( $A$13:A13 )-1 ) -> key_cat_type | C13: 大分類キー | D13: キー大分類キー | E13: INT | F13: 4 | G13: =VLOOKUP($E13, sql_type[#All], '<SQL> '!$E$3, FALSE ) -> INTEGER | I13: =OFFSET( E13,0,1) -> 4 | J13: Y | K13: Y | M13: {="ITM_"&UPPER(RIGHT(OFFSET(D13,S13,0),LEN(OFFSET(D13,S13,0))-4))&"_"&_xlfn.IFNA(_xlfn.IFS(K13="Y","PKEY",L13="Y","F"&UPPER(B13)),UPPER(B13))} -> ITM_CAT_TYPE_PKEY | N13: =M13&","&B13&","&OFFSET(G13,0,VLOOKUP($C$5,SQL[#All],2,FALSE) ) &", -- "&D13 -> ITM_CAT_TYPE_PKEY,key_cat_type,INTEGER, -- キー大分類キー | O13: =LEFT(LEFT("KEY_"&M13&REPT(" ",$O$6),$O$6)&": Final[str] = """&M13&""""&REPT(" ",$O$5),$O$5)&"# "&D13 -> KEY_ITM_CAT_TYPE_PKEY : Final[str] = "ITM_CAT_TYPE_PKEY" # キー大分類キー | P13: =$B13 & " " & VLOOKUP($E13, sql_type[#All], '<SQL> '!$E$3, FALSE )& " " & IFERROR( IF($K13="", VLOOKUP(K13, sql_notnull[#All], '<SQL> '!$E$3, FALSE ), VLOOKUP($K13, sql_pk[], '<SQL> '!$E$3, FALSE ) ), "" ) & ", -- " &$D13 -> key_cat_type INTEGER PRIMARY KEY, -- キー大分類キー | S13: -4
B14: =OFFSET( tbl_cat_type[[#Headers],[key_cat_type]], 0, ROWS( $A$13:A14 )-1 ) -> title_jp | C14: 日本語名称 | D14: 日本語名称 | E14: VARCHAR | F14: 100 | G14: =VLOOKUP($E14, sql_type[#All], '<SQL> '!$E$3, FALSE ) -> TEXT | J14: Y | M14: {="ITM_"&UPPER(RIGHT(OFFSET(D14,S14,0),LEN(OFFSET(D14,S14,0))-4))&"_"&_xlfn.IFNA(_xlfn.IFS(K14="Y","PKEY",L14="Y","F"&UPPER(B14)),UPPER(B14))} -> ITM_CAT_TYPE_TITLE_JP | N14: =M14&","&B14&","&OFFSET(G14,0,VLOOKUP($C$5,SQL[#All],2,FALSE) ) &", -- "&D14 -> ITM_CAT_TYPE_TITLE_JP,title_jp,TEXT, -- 日本語名称 | O14: =LEFT(LEFT("KEY_"&M14&REPT(" ",$O$6),$O$6)&": Final[str] = """&M14&""""&REPT(" ",$O$5),$O$5)&"# "&D14 -> KEY_ITM_CAT_TYPE_TITLE_JP : Final[str] = "ITM_CAT_TYPE_TITLE_JP" # 日本語名称 | P14: =$B14 & " " & VLOOKUP($E14, sql_type[#All], '<SQL> '!$E$3, FALSE )& " " & IFERROR( IF($K14="", VLOOKUP(K14, sql_notnull[#All], '<SQL> '!$E$3, FALSE ), VLOOKUP($K14, sql_pk[], '<SQL> '!$E$3, FALSE ) ), "" ) & ", -- " &$D14 -> title_jp TEXT , -- 日本語名称 | S14: -5
B15: =OFFSET( tbl_cat_type[[#Headers],[key_cat_type]], 0, ROWS( $A$13:A15 )-1 ) -> title_en | C15: 英語コード | D15: 英語コード | E15: VARCHAR | F15: 100 | G15: =VLOOKUP($E15, sql_type[#All], '<SQL> '!$E$3, FALSE ) -> TEXT | J15: Y | M15: {="ITM_"&UPPER(RIGHT(OFFSET(D15,S15,0),LEN(OFFSET(D15,S15,0))-4))&"_"&_xlfn.IFNA(_xlfn.IFS(K15="Y","PKEY",L15="Y","F"&UPPER(B15)),UPPER(B15))} -> ITM_CAT_TYPE_TITLE_EN | N15: =M15&","&B15&","&OFFSET(G15,0,VLOOKUP($C$5,SQL[#All],2,FALSE) ) &", -- "&D15 -> ITM_CAT_TYPE_TITLE_EN,title_en,TEXT, -- 英語コード | O15: =LEFT(LEFT("KEY_"&M15&REPT(" ",$O$6),$O$6)&": Final[str] = """&M15&""""&REPT(" ",$O$5),$O$5)&"# "&D15 -> KEY_ITM_CAT_TYPE_TITLE_EN : Final[str] = "ITM_CAT_TYPE_TITLE_EN" # 英語コード | P15: =$B15 & " " & VLOOKUP($E15, sql_type[#All], '<SQL> '!$E$3, FALSE )& " " & IFERROR( IF($K15="", VLOOKUP(K15, sql_notnull[#All], '<SQL> '!$E$3, FALSE ), VLOOKUP($K15, sql_pk[], '<SQL> '!$E$3, FALSE ) ), "" ) & ", -- " &$D15 -> title_en TEXT , -- 英語コード | S15: -6
B16: path | C16: 保存先フォルダのパス | D16: 保存先フォルダのパス | E16: TEXT | G16: =VLOOKUP($E16, sql_type[#All], '<SQL> '!$E$3, FALSE ) -> TEXT | J16: Y | M16: {="ITM_"&UPPER(RIGHT(OFFSET(D16,S16,0),LEN(OFFSET(D16,S16,0))-4))&"_"&_xlfn.IFNA(_xlfn.IFS(K16="Y","PKEY",L16="Y","F"&UPPER(B16)),UPPER(B16))} -> ITM_CAT_TYPE_PATH | N16: =M16&","&B16&","&OFFSET(G16,0,VLOOKUP($C$5,SQL[#All],2,FALSE) ) &", -- "&D16 -> ITM_CAT_TYPE_PATH,path,TEXT, -- 保存先フォルダのパス | O16: =LEFT(LEFT("KEY_"&M16&REPT(" ",$O$6),$O$6)&": Final[str] = """&M16&""""&REPT(" ",$O$5),$O$5)&"# "&D16 -> KEY_ITM_CAT_TYPE_PATH : Final[str] = "ITM_CAT_TYPE_PATH" # 保存先フォルダのパス | P16: =$B16 & " " & VLOOKUP($E16, sql_type[#All], '<SQL> '!$E$3, FALSE )& " " & IFERROR( IF($K16="", VLOOKUP(K16, sql_notnull[#All], '<SQL> '!$E$3, FALSE ), VLOOKUP($K16, sql_pk[], '<SQL> '!$E$3, FALSE ) ), "" ) & ", -- " &$D16 -> path TEXT , -- 保存先フォルダのパス | S16: -7
S17: -8
A19: 基準大分類DB
B20: テーブル名 | C20: 物理名 | D20: tbl_cat_major | N20: =UPPER( D20 ) & "," &D20 & ",," -> TBL_CAT_MAJOR,tbl_cat_major,, | O20: =LEFT( LEFT("KEY_"&UPPER(D20)&REPT(" ",$O$6),$O$6) & ": Final[str] = """&UPPER(D20)&"""" & REPT(" ",$O$5),$O$5 ) & "# " &D21 -> KEY_TBL_CAT_MAJOR : Final[str] = "TBL_CAT_MAJOR" # 基準大分類テーブル
C21: 論理名 | D21: 基準大分類テーブル
B22: カラム名 | E22: データ型 | J22: 制約 | N22: CREATE
B23: 物理名 | C23: 論理名 | D23: 概要 | E23: Type | F23: Byte | G23: SQLite | H23: SQL Server | I23: MongoDB | J23: NOT_NULL | K23: PK | L23: FK | N23: CSV | P23: SQLite | Q23: SQL Server | R23: MongoDB
B24: =OFFSET( tbl_cat_major[[#Headers],[key_cat_major]], 0, ROWS( $A$24:A24 )-1 ) -> key_cat_major | C24: 中分類キー | D24: 中分類キー | E24: INT | F24: 4 | G24: =VLOOKUP($E24, sql_type[#All], '<SQL> '!$E$3, FALSE ) -> INTEGER | J24: Y | K24: Y | M24: {="ITM_"&UPPER(RIGHT(OFFSET(D24,S24,0),LEN(OFFSET(D24,S24,0))-4))&"_"&_xlfn.IFNA(_xlfn.IFS(K24="Y","PKEY",L24="Y","F"&UPPER(B24)),UPPER(B24))} -> ITM_CAT_MAJOR_PKEY | N24: =M24&","&B24&","&OFFSET(G24,0,VLOOKUP($C$5,SQL[#All],2,FALSE) ) &", -- "&D24 -> ITM_CAT_MAJOR_PKEY,key_cat_major,INTEGER, -- 中分類キー | O24: =LEFT(LEFT("KEY_"&M24&REPT(" ",$O$6),$O$6)&": Final[str] = """&M24&""""&REPT(" ",$O$5),$O$5)&"# "&D24 -> KEY_ITM_CAT_MAJOR_PKEY : Final[str] = "ITM_CAT_MAJOR_PKEY" # 中分類キー | P24: =$B24 & " " & VLOOKUP($E24, sql_type[#All], '<SQL> '!$E$3, FALSE )& " " & IFERROR( IF($K24="", VLOOKUP(K24, sql_notnull[#All], '<SQL> '!$E$3, FALSE ), VLOOKUP($K24, sql_pk[], '<SQL> '!$E$3, FALSE ) ), "" ) & ", -- " &$D24 -> key_cat_major INTEGER PRIMARY KEY, -- 中分類キー | S24: -4
B25: =OFFSET( tbl_cat_major[[#Headers],[key_cat_major]], 0, ROWS( $A$24:A25 )-1 ) -> title_jp | C25: 日本語名称 | D25: 日本語名称 | E25: VARCHAR | F25: 100 | G25: =VLOOKUP($E25, sql_type[#All], '<SQL> '!$E$3, FALSE ) -> TEXT | J25: Y | M25: {="ITM_"&UPPER(RIGHT(OFFSET(D25,S25,0),LEN(OFFSET(D25,S25,0))-4))&"_"&_xlfn.IFNA(_xlfn.IFS(K25="Y","PKEY",L25="Y","F"&UPPER(B25)),UPPER(B25))} -> ITM_CAT_MAJOR_TITLE_JP | N25: =M25&","&B25&","&OFFSET(G25,0,VLOOKUP($C$5,SQL[#All],2,FALSE) ) &", -- "&D25 -> ITM_CAT_MAJOR_TITLE_JP,title_jp,TEXT, -- 日本語名称 | O25: =LEFT(LEFT("KEY_"&M25&REPT(" ",$O$6),$O$6)&": Final[str] = """&M25&""""&REPT(" ",$O$5),$O$5)&"# "&D25 -> KEY_ITM_CAT_MAJOR_TITLE_JP : Final[str] = "ITM_CAT_MAJOR_TITLE_JP" # 日本語名称 | P25: =$B25 & " " & VLOOKUP($E25, sql_type[#All], '<SQL> '!$E$3, FALSE )& " " & IFERROR( IF($K25="", VLOOKUP(K25, sql_notnull[#All], '<SQL> '!$E$3, FALSE ), VLOOKUP($K25, sql_pk[], '<SQL> '!$E$3, FALSE ) ), "" ) & ", -- " &$D25 -> title_jp TEXT , -- 日本語名称 | S25: -5
B26: =OFFSET( tbl_cat_major[[#Headers],[key_cat_major]], 0, ROWS( $A$24:A26 )-1 ) -> title_en | C26: 英語名称 | D26: 英語名称 | E26: VARCHAR | F26: 100 | G26: =VLOOKUP($E26, sql_type[#All], '<SQL> '!$E$3, FALSE ) -> TEXT | J26: Y | M26: {="ITM_"&UPPER(RIGHT(OFFSET(D26,S26,0),LEN(OFFSET(D26,S26,0))-4))&"_"&_xlfn.IFNA(_xlfn.IFS(K26="Y","PKEY",L26="Y","F"&UPPER(B26)),UPPER(B26))} -> ITM_CAT_MAJOR_TITLE_EN | N26: =M26&","&B26&","&OFFSET(G26,0,VLOOKUP($C$5,SQL[#All],2,FALSE) ) &", -- "&D26 -> ITM_CAT_MAJOR_TITLE_EN,title_en,TEXT, -- 英語名称 | O26: =LEFT(LEFT("KEY_"&M26&REPT(" ",$O$6),$O$6)&": Final[str] = """&M26&""""&REPT(" ",$O$5),$O$5)&"# "&D26 -> KEY_ITM_CAT_MAJOR_TITLE_EN : Final[str] = "ITM_CAT_MAJOR_TITLE_EN" # 英語名称 | P26: =$B26 & " " & VLOOKUP($E26, sql_type[#All], '<SQL> '!$E$3, FALSE )& " " & IFERROR( IF($K26="", VLOOKUP(K26, sql_notnull[#All], '<SQL> '!$E$3, FALSE ), VLOOKUP($K26, sql_pk[], '<SQL> '!$E$3, FALSE ) ), "" ) & ", -- " &$D26 -> title_en TEXT , -- 英語名称 | S26: -6
A27: =B27=B13 -> TRUE | B27: =OFFSET( tbl_cat_major[[#Headers],[key_cat_major]], 0, ROWS( $A$24:A27 )-1 ) -> key_cat_type | C27: 対応する大分類 | D27: 対応する大分類key_cat_type | E27: INT | F27: 4 | G27: =VLOOKUP($E27, sql_type[#All], '<SQL> '!$E$3, FALSE ) -> INTEGER | J27: Y | L27: Y | M27: {="ITM_"&UPPER(RIGHT(OFFSET(D27,S27,0),LEN(OFFSET(D27,S27,0))-4))&"_"&_xlfn.IFNA(_xlfn.IFS(K27="Y","PKEY",L27="Y","F"&UPPER(B27)),UPPER(B27))} -> ITM_CAT_MAJOR_FKEY_CAT_TYPE | N27: =M27&","&B27&","&OFFSET(G27,0,VLOOKUP($C$5,SQL[#All],2,FALSE) ) &", -- "&D27 -> ITM_CAT_MAJOR_FKEY_CAT_TYPE,key_cat_type,INTEGER, -- 対応する大分類key_cat_type | O27: =LEFT(LEFT("KEY_"&M27&REPT(" ",$O$6),$O$6)&": Final[str] = """&M27&""""&REPT(" ",$O$5),$O$5)&"# "&D27 -> KEY_ITM_CAT_MAJOR_FKEY_CAT_TYPE : Final[str] = "ITM_CAT_MAJOR_FKEY_CAT_TYPE" # 対応する大分類key_cat_type | P27: =$B27 & " " & VLOOKUP($E27, sql_type[#All], '<SQL> '!$E$3, FALSE )& " " & IFERROR( IF($K27="", VLOOKUP(K27, sql_notnull[#All], '<SQL> '!$E$3, FALSE ), VLOOKUP($K27, sql_pk[], '<SQL> '!$E$3, FALSE ) ), "" ) & ", -- " &$D27 -> key_cat_type INTEGER , -- 対応する大分類key_cat_type | S27: -7
B28: path | C28: 保存先フォルダのパス | D28: 保存先フォルダのパス | E28: TEXT | G28: =VLOOKUP($E28, sql_type[#All], '<SQL> '!$E$3, FALSE ) -> TEXT | J28: Y | M28: {="ITM_"&UPPER(RIGHT(OFFSET(D28,S28,0),LEN(OFFSET(D28,S28,0))-4))&"_"&_xlfn.IFNA(_xlfn.IFS(K28="Y","PKEY",L28="Y","F"&UPPER(B28)),UPPER(B28))} -> ITM_CAT_MAJOR_PATH | N28: =M28&","&B28&","&OFFSET(G28,0,VLOOKUP($C$5,SQL[#All],2,FALSE) ) &", -- "&D28 -> ITM_CAT_MAJOR_PATH,path,TEXT, -- 保存先フォルダのパス | O28: =LEFT(LEFT("KEY_"&M28&REPT(" ",$O$6),$O$6)&": Final[str] = """&M28&""""&REPT(" ",$O$5),$O$5)&"# "&D28 -> KEY_ITM_CAT_MAJOR_PATH : Final[str] = "ITM_CAT_MAJOR_PATH" # 保存先フォルダのパス | S28: -8
S29: -9
A31: 基準小分類DB
B32: テーブル名 | C32: 物理名 | D32: tbl_cat_sub | N32: =UPPER( D32 ) & "," &D32 & ",," -> TBL_CAT_SUB,tbl_cat_sub,, | O32: =LEFT( LEFT("KEY_"&UPPER(D32)&REPT(" ",$O$6),$O$6) & ": Final[str] = """&UPPER(D32)&"""" & REPT(" ",$O$5),$O$5 ) & "# " &D33 -> KEY_TBL_CAT_SUB : Final[str] = "TBL_CAT_SUB" # 基準小分類テーブル
C33: 論理名 | D33: 基準小分類テーブル
B34: カラム名 | E34: データ型 | J34: 制約 | N34: CREATE
B35: 物理名 | C35: 論理名 | D35: 概要 | E35: Type | F35: Byte | G35: SQLite | H35: SQL Server | I35: MongoDB | J35: NOT_NULL | K35: PK | L35: FK | N35: CSV | P35: SQLite | Q35: SQL Server | R35: MongoDB
B36: =OFFSET( tbl_cat_sub[[#Headers],[key_cat_sub]], 0, ROWS( $A$36:A36 )-1 ) -> key_cat_sub | C36: 小分類キー | D36: 小分類キー | E36: INT | F36: 4 | G36: =VLOOKUP($E36, sql_type[#All], '<SQL> '!$E$3, FALSE ) -> INTEGER | I36: 4 | J36: Y | K36: Y | M36: {="ITM_"&UPPER(RIGHT(OFFSET(D36,S36,0),LEN(OFFSET(D36,S36,0))-4))&"_"&_xlfn.IFNA(_xlfn.IFS(K36="Y","PKEY",L36="Y","F"&UPPER(B36)),UPPER(B36))} -> ITM_CAT_SUB_PKEY | N36: =M36&","&B36&","&OFFSET(G36,0,VLOOKUP($C$5,SQL[#All],2,FALSE) ) &", -- "&D36 -> ITM_CAT_SUB_PKEY,key_cat_sub,INTEGER, -- 小分類キー | O36: =LEFT(LEFT("KEY_"&M36&REPT(" ",$O$6),$O$6)&": Final[str] = """&M36&""""&REPT(" ",$O$5),$O$5)&"# "&D36 -> KEY_ITM_CAT_SUB_PKEY : Final[str] = "ITM_CAT_SUB_PKEY" # 小分類キー | P36: =$B36 & " " & VLOOKUP($E36, sql_type[#All], '<SQL> '!$E$3, FALSE )& " " & IFERROR( IF($K36="", VLOOKUP(K36, sql_notnull[#All], '<SQL> '!$E$3, FALSE ), VLOOKUP($K36, sql_pk[], '<SQL> '!$E$3, FALSE ) ), "" ) & ", -- " &$D36 -> key_cat_sub INTEGER PRIMARY KEY, -- 小分類キー | S36: -4
B37: =OFFSET( tbl_cat_sub[[#Headers],[key_cat_sub]], 0, ROWS( $A$36:A37 )-1 ) -> title_jp | C37: 日本語名称 | D37: 日本語名称 | E37: VARCHAR | F37: 100 | G37: =VLOOKUP($E37, sql_type[#All], '<SQL> '!$E$3, FALSE ) -> TEXT | I37: 100 | J37: Y | M37: {="ITM_"&UPPER(RIGHT(OFFSET(D37,S37,0),LEN(OFFSET(D37,S37,0))-4))&"_"&_xlfn.IFNA(_xlfn.IFS(K37="Y","PKEY",L37="Y","F"&UPPER(B37)),UPPER(B37))} -> ITM_CAT_SUB_TITLE_JP | N37: =M37&","&B37&","&OFFSET(G37,0,VLOOKUP($C$5,SQL[#All],2,FALSE) ) &", -- "&D37 -> ITM_CAT_SUB_TITLE_JP,title_jp,TEXT, -- 日本語名称 | O37: =LEFT(LEFT("KEY_"&M37&REPT(" ",$O$6),$O$6)&": Final[str] = """&M37&""""&REPT(" ",$O$5),$O$5)&"# "&D37 -> KEY_ITM_CAT_SUB_TITLE_JP : Final[str] = "ITM_CAT_SUB_TITLE_JP" # 日本語名称 | P37: =$B37 & " " & VLOOKUP($E37, sql_type[#All], '<SQL> '!$E$3, FALSE )& " " & IFERROR( IF($K37="", VLOOKUP(K37, sql_notnull[#All], '<SQL> '!$E$3, FALSE ), VLOOKUP($K37, sql_pk[], '<SQL> '!$E$3, FALSE ) ), "" ) & ", -- " &$D37 -> title_jp TEXT , -- 日本語名称 | S37: -5
B38: =OFFSET( tbl_cat_sub[[#Headers],[key_cat_sub]], 0, ROWS( $A$36:A38 )-1 ) -> title_en | C38: 英語名称 | D38: 英語名称 | E38: VARCHAR | F38: 100 | G38: =VLOOKUP($E38, sql_type[#All], '<SQL> '!$E$3, FALSE ) -> TEXT | I38: 100 | J38: Y | M38: {="ITM_"&UPPER(RIGHT(OFFSET(D38,S38,0),LEN(OFFSET(D38,S38,0))-4))&"_"&_xlfn.IFNA(_xlfn.IFS(K38="Y","PKEY",L38="Y","F"&UPPER(B38)),UPPER(B38))} -> ITM_CAT_SUB_TITLE_EN | N38: =M38&","&B38&","&OFFSET(G38,0,VLOOKUP($C$5,SQL[#All],2,FALSE) ) &", -- "&D38 -> ITM_CAT_SUB_TITLE_EN,title_en,TEXT, -- 英語名称 | O38: =LEFT(LEFT("KEY_"&M38&REPT(" ",$O$6),$O$6)&": Final[str] = """&M38&""""&REPT(" ",$O$5),$O$5)&"# "&D38 -> KEY_ITM_CAT_SUB_TITLE_EN : Final[str] = "ITM_CAT_SUB_TITLE_EN" # 英語名称 | P38: =$B38 & " " & VLOOKUP($E38, sql_type[#All], '<SQL> '!$E$3, FALSE )& " " & IFERROR( IF($K38="", VLOOKUP(K38, sql_notnull[#All], '<SQL> '!$E$3, FALSE ), VLOOKUP($K38, sql_pk[], '<SQL> '!$E$3, FALSE ) ), "" ) & ", -- " &$D38 -> title_en TEXT , -- 英語名称 | S38: -6
A39: =B39=B24 -> TRUE | B39: =OFFSET( tbl_cat_sub[[#Headers],[key_cat_sub]], 0, ROWS( $A$36:A39 )-1 ) -> key_cat_major | C39: 対応する中分類 | D39: 対応する中分類key_cat_major | E39: INT | F39: 4 | G39: =VLOOKUP($E39, sql_type[#All], '<SQL> '!$E$3, FALSE ) -> INTEGER | I39: 4 | J39: Y | L39: Y | M39: {="ITM_"&UPPER(RIGHT(OFFSET(D39,S39,0),LEN(OFFSET(D39,S39,0))-4))&"_"&_xlfn.IFNA(_xlfn.IFS(K39="Y","PKEY",L39="Y","F"&UPPER(B39)),UPPER(B39))} -> ITM_CAT_SUB_FKEY_CAT_MAJOR | N39: =M39&","&B39&","&OFFSET(G39,0,VLOOKUP($C$5,SQL[#All],2,FALSE) ) &", -- "&D39 -> ITM_CAT_SUB_FKEY_CAT_MAJOR,key_cat_major,INTEGER, -- 対応する中分類key_cat_major | O39: =LEFT(LEFT("KEY_"&M39&REPT(" ",$O$6),$O$6)&": Final[str] = """&M39&""""&REPT(" ",$O$5),$O$5)&"# "&D39 -> KEY_ITM_CAT_SUB_FKEY_CAT_MAJOR : Final[str] = "ITM_CAT_SUB_FKEY_CAT_MAJOR" # 対応する中分類key_cat_major | P39: =$B39 & " " & VLOOKUP($E39, sql_type[#All], '<SQL> '!$E$3, FALSE )& " " & IFERROR( IF($K39="", VLOOKUP(K39, sql_notnull[#All], '<SQL> '!$E$3, FALSE ), VLOOKUP($K39, sql_pk[], '<SQL> '!$E$3, FALSE ) ), "" ) & ", -- " &$D39 -> key_cat_major INTEGER , -- 対応する中分類key_cat_major | S39: -7
B40: path | C40: 保存先フォルダのパス | D40: 保存先フォルダのパス | E40: TEXT | G40: =VLOOKUP($E40, sql_type[#All], '<SQL> '!$E$3, FALSE ) -> TEXT | J40: Y | M40: {="ITM_"&UPPER(RIGHT(OFFSET(D40,S40,0),LEN(OFFSET(D40,S40,0))-4))&"_"&_xlfn.IFNA(_xlfn.IFS(K40="Y","PKEY",L40="Y","F"&UPPER(B40)),UPPER(B40))} -> ITM_CAT_SUB_PATH | N40: =M40&","&B40&","&OFFSET(G40,0,VLOOKUP($C$5,SQL[#All],2,FALSE) ) &", -- "&D40 -> ITM_CAT_SUB_PATH,path,TEXT, -- 保存先フォルダのパス | O40: =LEFT(LEFT("KEY_"&M40&REPT(" ",$O$6),$O$6)&": Final[str] = """&M40&""""&REPT(" ",$O$5),$O$5)&"# "&D40 -> KEY_ITM_CAT_SUB_PATH : Final[str] = "ITM_CAT_SUB_PATH" # 保存先フォルダのパス | P40: =$B40 & " " & VLOOKUP($E40, sql_type[#All], '<SQL> '!$E$3, FALSE )& " " & IFERROR( IF($K40="", VLOOKUP(K40, sql_notnull[#All], '<SQL> '!$E$3, FALSE ), VLOOKUP($K40, sql_pk[], '<SQL> '!$E$3, FALSE ) ), "" ) & ", -- " &$D40 -> path TEXT , -- 保存先フォルダのパス | S40: -8
S41: -9
A44: 状態DB
B45: テーブル名 | C45: 物理名 | D45: tbl_cat_state | N45: =UPPER( D45 ) & "," &D45 & ",," -> TBL_CAT_STATE,tbl_cat_state,, | O45: =LEFT( LEFT("KEY_"&UPPER(D45)&REPT(" ",$O$6),$O$6) & ": Final[str] = """&UPPER(D45)&"""" & REPT(" ",$O$5),$O$5 ) & "# " &D46 -> KEY_TBL_CAT_STATE : Final[str] = "TBL_CAT_STATE" # 基準小分類テーブル
C46: 論理名 | D46: 基準小分類テーブル
...

Sheet tbl_rules
A1: key_rule | B1: id_rule | C1: name_rule | D1: key_cat_sub | E1: link | F1: key_cat_state | G1: created_date | H1: update_date
A2: 1 | B2: PA011 | C2: 経営理念 | D2: 1 | E2: https://www4.kitei-kanri.jp/gf7/seikoepson/browse.php?action_treeList&rule=674&public_id=1 | F2: 1 | G2: 32874 | H2: 32874
A3: 2 | B3: PB011 | C3: 企業行動原則 | D3: 2 | E3: https://www4.kitei-kanri.jp/gf7/seikoepson/browse.php?action_treeList&rule=675&public_id=1 | F3: 1 | G3: 32874 | H3: 32874
A4: 3 | B4: PB111 | C4: エプソングループ製品安全に関する基本方針 | D4: 3 | E4: https://www4.kitei-kanri.jp/gf7/seikoepson/browse.php?action_treeList&rule=676&public_id=1 | F4: 1 | G4: 32874 | H4: 32874
A5: 4 | B5: PB121 | C5: エプソングループ労働安全衛生基本方針 | D5: 3 | E5: https://www4.kitei-kanri.jp/gf7/seikoepson/browse.php?action_treeList&rule=677&public_id=1 | F5: 1 | G5: 32874 | H5: 32874
A6: 5 | B6: PB131 | C6: エプソングループ人権方針 | D6: 3 | E6: https://www4.kitei-kanri.jp/gf7/seikoepson/browse.php?action_treeList&rule=678&public_id=1 | F6: 1 | G6: 32874 | H6: 32874
A7: 6 | B7: PB141 | C7: エプソングループAI倫理原則 | D7: 3 | E7: https://www4.kitei-kanri.jp/gf7/seikoepson/browse.php?action_treeList&rule=680&public_id=1 | F7: 1 | G7: 32874 | H7: 32874
A8: 7 | B8: PB151 | C8: 情報セキュリティー基本方針 | D8: 3 | E8: https://www4.kitei-kanri.jp/gf7/seikoepson/browse.php?action_treeList&rule=681&public_id=1 | F8: 1 | G8: 32874 | H8: 32874
A9: 8 | B9: PB161 | C9: エプソングループ調達基本方針 | D9: 3 | E9: https://www4.kitei-kanri.jp/gf7/seikoepson/browse.php?action_treeList&rule=682&public_id=1 | F9: 1 | G9: 32874 | H9: 32874
A10: 9 | B10: PC011 | C10: エプソングローバル社員行動規範 | D10: 4 | E10: https://www4.kitei-kanri.jp/gf7/seikoepson/browse.php?action_treeList&rule=683&public_id=1 | F10: 1 | G10: 32874 | H10: 32874
A11: 10 | B11: SA011 | C11: 定款 | D11: 5 | E11: https://www4.kitei-kanri.jp/gf7/seikoepson/browse.php?action_treeList&rule=684&public_id=1 | F11: 1 | G11: 32874 | H11: 32874
A12: 11 | B12: SA021 | C12: 株式取扱規則 | D12: 5 | E12: https://www4.kitei-kanri.jp/gf7/seikoepson/browse.php?action_treeList&rule=685&public_id=1 | F12: 1 | G12: 32874 | H12: 32874
A13: 12 | B13: SA031 | C13: コーポレートガバナンス基本方針 | D13: 5 | E13: https://www4.kitei-kanri.jp/gf7/seikoepson/browse.php?action_treeList&rule=686&public_id=1 | F13: 1 | G13: 32874 | H13: 32874
... A810: 809 | B810: GC-0025 | C810: TV特性(LCD5200) | D810: 59 | E810: https://ei-core-02.apo.epson.net/prozou/html/document/view/313537340000000000000000000000000000/1 | F810: 1 | G810: 32874 | H810: 43124
A811: 810 | B811: GC-0029 | C811: LCCOMズレ | D811: 59 | E811: https://ei-core-02.apo.epson.net/prozou/html/document/view/313537330000000000000000000000000000/1 | F811: 1 | G811: 32874 | H811: 43091 | S811: プロジェクターに限定
A812: 811 | B812: GC-0030 | C812: 上下ゴースト | D812: 59 | E812: https://ei-core-02.apo.epson.net/prozou/html/document/view/313537430000000000000000000000000000/1 | F812: 1 | G812: 32874 | H812: 43192 | S812: プロジェクターに限定
A813: 812 | B813: GC-0031 | C813: 透過率コントラスト | D813: 59 | E813: https://ei-core-02.apo.epson.net/prozou/html/document/view/313539480000000000000000000000000000/1 | F813: 1 | G813: 32874 | H813: 44944 | S813: プロジェクターに限定
A814: 813 | B814: GC-0032 | C814: 白線上黒線 | D814: 59 | E814: https://ei-core-02.apo.epson.net/prozou/html/document/view/313537370000000000000000000000000000/1 | F814: 1 | G814: 32874 | H814: 43124 | S814: プロジェクターに限定
A815: 814 | B815: GC-0033 | C815: ドメイン数値化 | D815: 59 | E815: https://ei-core-02.apo.epson.net/prozou/html/document/view/313537240000000000000000000000000000/1 | F815: 1 | G815: 32874 | H815: 43077 | S815: プロジェクターに限定
A816: 815 | B816: GC-0034 | C816: 入力端子容量 | D816: 59 | E816: https://ei-core-02.apo.epson.net/prozou/html/document/view/313537190000000000000000000000000000/1 | F816: 1 | G816: 32874 | H816: 43077 | S816: プロジェクターに限定
A817: 816 | B817: GC-0035 | C817: 液晶応答速度(LCD5200) | D817: 59 | E817: https://ei-core-02.apo.epson.net/prozou/html/document/view/313537230000000000000000000000000000/1 | F817: 1 | G817: 32874 | H817: 43077 | S817: プロジェクターに限定
A818: 817 | B818: GC-0036 | C818: 静止画ドメイン | D818: 59 | E818: https://ei-core-02.apo.epson.net/prozou/html/document/view/313537360000000000000000000000000000/1 | F818: 1 | G818: 32874 | H818: 43094 | S818: プロジェクターに限定
A819: 818 | B819: GC-0039 | C819: 動画ドメイン（手動測定） | D819: 59 | E819: https://ei-core-02.apo.epson.net/prozou/html/document/view/313537350000000000000000000000000000/1595552 | F819: 1 | G819: 32874 | H819: 45803.667 | S819: プロジェクターに限定
A820: 819 | B820: GC-0040 | C820: CV特性 | D820: 59 | E820: https://ei-core-02.apo.epson.net/prozou/html/document/view/313537170000000000000000000000000000/1 | F820: 1 | G820: 32874 | H820: 43069 | S820: プロジェクターに限定
A821: 820 | B821: GC-0041 | C821: 消費電流･消費電力 | D821: 59 | E821: https://ei-core-02.apo.epson.net/prozou/html/document/view/313537200000000000000000000000000000/1 | F821: 1 | G821: 32874 | H821: 43077 | S821: プロジェクターに限定
A822: 821 | B822: GC-0042 | C822: 絶対最大定格 | D822: 59 | E822: https://ei-core-02.apo.epson.net/prozou/html/document/view/313537210000000000000000000000000000/1 | F822: 1 | G822: 32874 | H822: 43077 | S822: プロジェクターに限定
... A826: 825 | B826: GC-0052 | C826: 動画縦帯 | D826: 59 | E826: https://ei-core-02.apo.epson.net/prozou/html/document/view/313537220000000000000000000000000000/1 | F826: 1 | G826: 32874 | H826: 43077 | S826: プロジェクターに限定
A827: 826 | B827: GC-0058 | C827: アプリケーションCD同梱業務処理基準 | D827: 59 | E827: https://ei-core-02.apo.epson.net/prozou/html/document/view/313537100000000000000000000000000000/1 | F827: 1 | G827: 32874 | H827: 42796
A828: 827 | B828: GC-0060 | C828: 光リーク画素ムラ | D828: 59 | E828: https://ei-core-02.apo.epson.net/prozou/html/document/view/313537530000000000000000000000000000/1 | F828: 1 | G828: 32874 | H828: 43272 | S828: プロジェクターに限定
A829: 828 | B829: GC-0061 | C829: 表示ムラ | D829: 59 | E829: https://ei-core-02.apo.epson.net/prozou/html/document/view/313537870000000000000000000000000000/1 | F829: 1 | G829: 32874 | H829: 43521 | S829: プロジェクターに限定
A830: 829 | B830: GC-0062 | C830: 周辺光再反射 | D830: 59 | E830: https://ei-core-02.apo.epson.net/prozou/html/document/view/313537550000000000000000000000000000/1 | F830: 1 | G830: 32874 | H830: 43272 | S830: プロジェクターに限定
A831: 830 | B831: GC-0063 | C831: 井桁ムラ | D831: 59 | E831: https://ei-core-02.apo.epson.net/prozou/html/document/view/313537570000000000000000000000000000/1 | F831: 1 | G831: 32874 | H831: 43272 | S831: プロジェクターに限定
A832: 831 | B832: GC-0064 | C832: フックけられ | D832: 59 | E832: https://ei-core-02.apo.epson.net/prozou/html/document/view/313537580000000000000000000000000000/1 | F832: 1 | G832: 32874 | H832: 43272 | S832: プロジェクターに限定
A833: 832 | B833: GC-0065 | C833: 左右画素ムラ | D833: 59 | E833: https://ei-core-02.apo.epson.net/prozou/html/document/view/313537540000000000000000000000000000/1 | F833: 1 | G833: 32874 | H833: 43272 | S833: プロジェクターに限定
A834: 833 | B834: GC-0066 | C834: 配向性画素ムラ | D834: 59 | E834: https://ei-core-02.apo.epson.net/prozou/html/document/view/313537560000000000000000000000000000/1 | F834: 1 | G834: 32874 | H834: 43272 | S834: プロジェクターに限定
A835: 834 | B835: GC-0067 | C835: パネル表面温度 | D835: 59 | E835: https://ei-core-02.apo.epson.net/prozou/html/document/view/313537710000000000000000000000000000/1 | F835: 1 | G835: 32874 | H835: 43340 | S835: プロジェクターに限定
A836: 835 | B836: GC-0071 | C836: ゴースト・VDDXマージン | D836: 59 | E836: https://ei-core-02.apo.epson.net/prozou/html/document/view/313537250000000000000000000000000000/1 | F836: 1 | G836: 32874 | H836: 43182 | S836: プロジェクターに限定
A837: 836 | B837: GC-0072 | C837: 帯ムラマージン | D837: 59 | E837: https://ei-core-02.apo.epson.net/prozou/html/document/view/313537260000000000000000000000000000/1 | F837: 1 | G837: 32874 | H837: 43182 | S837: プロジェクターに限定
A838: 837 | B838: GC-0073 | C838: 高温画素ズレ | D838: 59 | E838: https://ei-core-02.apo.epson.net/prozou/html/document/view/313537280000000000000000000000000000/1 | F838: 1 | G838: 32874 | H838: 43077 | S838: プロジェクターに限定
A839: 838 | B839: GC-0074 | C839: FPC斜め引っ張り | D839: 59 | E839: https://ei-core-02.apo.epson.net/prozou/html/document/view/313537290000000000000000000000000000/1 | F839: 1 | G839: 32874 | H839: 43077 | S839: プロジェクターに限定
...

Sheet tbl_cat_type
A1: key_cat_type | B1: title_jp | C1: title_en | D1: path
A2: 1 | B2: エプソン例規集 | C2: RULES_CORP | D2: corp_rules
A3: 2 | B3: 全社EQS | C3: EQS_CORP | D3: corp_eqs
A4: 3 | B4: VP事業部基準 | C4: RULES_VP | D4: vp_rules
A5: 4 | B5: VP事業部EQS | C5: EQS_VP | D5: vp_eqs
A6: 5 | B6: VP業務処理基準 | C6: OPS_VP | D6: vp_ops
A7: 6 | B7: VP規格・標準 | C7: STANDARD_VP | D7: vp_standard

Sheet tbl_cat_major
A1: key_cat_major | B1: title_jp | C1: title_en | D1: key_cat_type | E1: path
A2: 1 | B2: 理念 | C2: PHILOSOPHY | D2: 1 | E2: philosophy | F2: =TEXT(tbl_cat_major[[#This Row],[key_cat_major]],"")
A3: 2 | B3: SEC規程 | C3: OFFICE | D3: 1 | E3: office | F3: =TEXT(tbl_cat_major[[#This Row],[key_cat_major]],"")
A4: 3 | B4: グループ規程 | C4: GROUP | D4: 1 | E4: group | F4: =TEXT(tbl_cat_major[[#This Row],[key_cat_major]],"")
A5: 4 | B5: 安全性 | C5: SAFETY | D5: 2 | E5: safety | F5: =TEXT(tbl_cat_major[[#This Row],[key_cat_major]],"")
A6: 5 | B6: 含有化学物質 | C6: CHEMICAL | D6: 2 | E6: chem | F6: =TEXT(tbl_cat_major[[#This Row],[key_cat_major]],"")
A7: 6 | B7: 化学製品 | C7: CHEMICAL_PRODUCTS | D7: 2 | E7: chem_prod | F7: =TEXT(tbl_cat_major[[#This Row],[key_cat_major]],"")
A8: 7 | B8: 環境 | C8: ENVIROMENT | D8: 2 | E8: env | F8: =TEXT(tbl_cat_major[[#This Row],[key_cat_major]],"")
A9: 8 | B9: EMC | C9: EMC | D9: 2 | E9: emc | F9: =TEXT(tbl_cat_major[[#This Row],[key_cat_major]],"")
A10: 9 | B10: セキュリティ | C10: SECURITY | D10: 2 | E10: security | F10: =TEXT(tbl_cat_major[[#This Row],[key_cat_major]],"")
A11: 10 | B11: 輸送 | C11: TRANSPORT | D11: 2 | E11: trans | F11: =TEXT(tbl_cat_major[[#This Row],[key_cat_major]],"")
A12: 11 | B12: ウィスカ | C12: Wisker | D12: 2 | E12: wisker | F12: =TEXT(tbl_cat_major[[#This Row],[key_cat_major]],"")
A13: 12 | B13: AI | C13: AI | D13: 2 | E13: ai | F13: =TEXT(tbl_cat_major[[#This Row],[key_cat_major]],"")
... A40: 39 | B40: 一般 | C40: GENERAL | D40: 6 | E40: general | F40: =TEXT(tbl_cat_major[[#This Row],[key_cat_major]],"")

Sheet tbl_cat_sub
A1: key_cat_sub | B1: title_jp | C1: title_en | D1: key_cat_major | E1: path
A2: 1 | B2: 経営理念 | C2: MANAGEMENT_PHILOSOPHY | D2: 1 | E2: mgmt_phil
A3: 2 | B3: 企業行動原則 | C3: CORPORATE_ACTION_PRINCIPLES | D3: 1 | E3: corp_actp
A4: 3 | B4: 方針類 | C4: POLICY_CATEGORY | D4: 1 | E4: pol_cat
A5: 4 | B5: 社員行動規範 | C5: EMPLOYEE_CODE_OF_CONDUCT | D5: 1 | E5: emp_coc
A6: 5 | B6: 定款と付属規程 | C6: ARTICLES_OF_INCORPORATION_AND_SUPPLEMENTARY_REGULATIONS | D6: 2 | E6: aoi_supp
A7: 6 | B7: ガバナンス | C7: GOVERNANCE | D7: 2 | E7: gov
A8: 7 | B8: コンプライアンス | C8: COMPLIANCE | D8: 2 | E8: comp
A9: 8 | B9: 規程管理 | C9: PROCEDURE_MANAGEMENT | D9: 2 | E9: proc_mgmt
A10: 9 | B10: 組織分掌 | C10: DIVISION_OF_ORGANIZATION | D10: 2 | E10: div_org
A11: 10 | B11: 経営会議 | C11: MANAGEMENT_MEETING | D11: 2 | E11: mgmt_mt
A12: 11 | B12: 職務権限 | C12: AUTHORITY | D12: 2 | E12: auth
A13: 12 | B13: 役員関連 | C13: OFFICER_RELATED | D13: 2 | E13: off_rel
... A105: 104 | B105: - | C105: - | D105: 39 | E105: null

Sheet tbl_cat_state
A1: key_cat_state | B1: title_jp | C1: title_en
A2: 0 | B2: 作成中 | C2: Draft
A3: 1 | B3: 制定版 | C3: Active
A4: 2 | B4: 廃止 | C4: Retired

Sheet tbl_request
A1: key_req | B1: key_rule | C1: id_cap | D1: title_capter | E1: title_section | F1: top_body | G1: low_body | H1: top_tbl | I1: top_fig | J1: low_tbl | K1: low_fig | L1: lead_time | M1: reference | N1: created_date | O1: update_date | P1: key_cat_request | Q1: key_cat_phase | R1: scope_product_genre | S1: scope_service_genre | T1: scope_equipment | U1: scope_pii | V1: scope_design_domain | W1: unique_search
A2: 1 | B2: 575 | C2: 1 | D2: プラグ残留電圧 | E2: 試験条件 | F2: ① 製品状態：プラグ残留電圧が最大となるよう設定する。 ② 周囲温度：常温常湿 ③ 対象製品：商用電源を使用する製品
A3: 2 | B3: 575 | C3: 1 | D3: プラグ残留電圧 | E3: 試験方法 | F3: ① 製品を１分以上動作させて電源プラグ抜き、１秒後のプラグに残留する電圧をストレージオシロスコープ等で測定する。 ② 測定は、放電するのに充分な時間間隔をおいて１０回以上おこない、その最大値を測定値とする。
A4: 3 | B4: 575 | C4: 1 | D4: プラグ残留電圧 | E4: 判定基準 | F4: プラグ残留電圧は時定数（ｔｉｍｅ ｃｏｎｓｔａｎｔ）１秒以下であること。 図のようにプラグに残留する電圧が３６．８％まで降下するのに1秒以下でなければならない。

Sheet tbl_cat_request
A1: key_cat_request | B1: title_jp | C1: title_en | D1: key_cat_req_type | E1: req_type
A2: 0 | B2: 全般 | D2: 0 | E2: 商品化に関わらない内容
A3: 1 | B3: 試験条件 | D3: 1 | E3: 商品化アクション
A4: 2 | B4: 試験内容 | D4: 2 | E4: 商品化説明
A5: 3 | B5: 合格基準 | D5: 3 | E5: 商品化チェック項目
A6: 4 | B6: 適合範囲 | D6: 4 | E6: 商品化アクション＆チェック項目

Sheet tbl_cat_phase
A1: key_cat_phase | B1: title_jp | C1: title_en
A2: 0 | B2: ~DR0
A3: 1 | B3: ~DR1
A4: 2 | B4: ~DR2
A5: 3 | B5: ~DR3
A6: 4 | B6: ~DR4
A7: 5 | B7: ~DR5

Sheet tbl_scp_sales_region
A1: key_scp_sales_region | B1: title_jp | C1: title_en | D1: country_code_2 | E1: country_code_3
A2: 0 | B2: アメリカ | C2: United States | D2: US | E2: USA
A3: 1 | B3: カナダ | C3: Canada | D3: CA | E3: CAN
A4: 2 | B4: EU | C4: EU | D4: EU | E4: —
A5: 3 | B5: フランス | C5: France | D5: FR | E5: FRA
A6: 4 | B6: イタリア | C6: Italy | D6: IT | E6: ITA
A7: 5 | B7: スペイン | C7: Spain | D7: ES | E7: ESP
A8: 6 | B8: 日本 | C8: Japan | D8: JP | E8: JPN
A9: 7 | B9: トルコ | C9: Turkey | D9: TR | E9: TUR
A10: 8 | B10: ウクライナ | C10: Ukraine | D10: UA | E10: UKR
A11: 9 | B11: 中国 | C11: China | D11: CN | E11: CHN
A12: 10 | B12: インド | C12: India | D12: IN | E12: IND
A13: 11 | B13: 台湾 | C13: Taiwan | D13: TW | E13: TWN
... A29: 27 | B29: アルゼンチン | C29: Argentina | D29: AR | E29: ARG

Sheet tbl_scp_product_genre
A1: key_scp_product_genre | B1: title_jp | C1: title_en | D1: hs_code
A2: 0 | B2: 全部
A3: 1 | B3: LCP本体
A4: 2 | B4: LCPオプション
A5: 3 | B5: スクリーン
A6: 4 | B6: 書画カメラ

Sheet tbl_scp_service_genre
A1: key_scp_service_genre | B1: title_jp | C1: title_en
A2: 0 | B2: PCアプリ
A3: 1 | B3: FW
A4: 2 | B4: SDK
A5: 3 | B5: Webページ
A6: 4 | B6: Webサービス

Sheet tbl_scp_equipment
A1: key_scp_equipment | B1: title_jp | C1: title_en
A2: 0 | B2: ACDC変換
A3: 1 | B3: ACアダプター
A4: 2 | B4: リチウムイオン電池
A5: 3 | B5: その他電池

Sheet tbl_scp_pii
A1: key_scp_pii | B1: title_jp | C1: title_en
A2: 0 | B2: 無し
A3: 1 | B3: 個人情報
A4: 2 | B4: 個人情報レベル2

Sheet tbl_scp_design_domain
A1: key_scp_design_domain | B1: title_jp | C1: title_en
A2: 0 | B2: メカ | C2: Mecha
A3: 1 | B3: エレキ | C3: Elec
A4: 2 | B4: ソフト | C4: Soft
A5: 3 | B5: 表示 | C5: Display
A6: 4 | B6: 梱包 | C6: Package
A7: 5 | B7: 認証 | C7: Certification
A8: 6 | B8: 製造 | C8: Manufacturing
